<?xml version="1.0" ?>
<!-- Generated using onshape-to-robot -->
<!-- Onshape document_id: dccc9867c88f4c00ebd285c5 / workspace_id: 4d6b4b67b32ea734f124cf6d -->
<robot name="rescue_rangers_arm">
  <!-- Link j5 -->
  <link name="j5">
    <inertial>
      <origin xyz="0 0 0" rpy="0 0 0"/>
      <mass value="1e-09"/>
      <inertia ixx="1e-09" ixy="0" ixz="0" iyy="1e-09" iyz="0" izz="1e-09"/>
    </inertial>
    <!-- Part h42p_020_s300_r_dummy2 -->
    <visual>
      <origin xyz="0.0659729 -0.0209888 0.97053" rpy="-1.5708 0 -0"/>
      <geometry>
        <mesh filename="package://rover_description/RescueRangersArmMeshes/h42p_020_s300_r_dummy2.stl"/>
      </geometry>
      <material name="h42p_020_s300_r_dummy2_material">
        <color rgba="0.647059 0.647059 0.647059 1"/>
      </material>
    </visual>
    <collision>
      <origin xyz="0.0659729 -0.0209888 0.97053" rpy="-1.5708 0 -0"/>
      <geometry>
        <mesh filename="package://rover_description/RescueRangersArmMeshes/h42p_020_s300_r_dummy2.stl"/>
      </geometry>
    </collision>
    <!-- Part j5 -->
    <visual>
      <origin xyz="0.0779729 1.12e-05 0.94953" rpy="0 -0 3.14159"/>
      <geometry>
        <mesh filename="package://rover_description/RescueRangersArmMeshes/j5.stl"/>
      </geometry>
      <material name="j5_material">
        <color rgba="0.615686 0.811765 0.929412 1"/>
      </material>
    </visual>
    <collision>
      <origin xyz="0.0779729 1.12e-05 0.94953" rpy="0 -0 3.14159"/>
      <geometry>
        <mesh filename="package://rover_description/RescueRangersArmMeshes/j5.stl"/>
      </geometry>
    </collision>
  </link>
  <!-- Link h42p_020_s300_r_dummy2 -->
  <link name="h42p_020_s300_r_dummy2">
    <inertial>
      <origin xyz="0 0 0" rpy="0 0 0"/>
      <mass value="1e-09"/>
      <inertia ixx="1e-09" ixy="0" ixz="0" iyy="1e-09" iyz="0" izz="1e-09"/>
    </inertial>
    <!-- Part h42p_020_s300_r_dummy2_2 -->
    <visual>
      <origin xyz="0 -0.021 -0.057" rpy="-1.5708 -1.5708 0"/>
      <geometry>
        <mesh filename="package://rover_description/RescueRangersArmMeshes/h42p_020_s300_r_dummy2.stl"/>
      </geometry>
      <material name="h42p_020_s300_r_dummy2_2_material">
        <color rgba="0.647059 0.647059 0.647059 1"/>
      </material>
    </visual>
    <collision>
      <origin xyz="0 -0.021 -0.057" rpy="-1.5708 -1.5708 0"/>
      <geometry>
        <mesh filename="package://rover_description/RescueRangersArmMeshes/h42p_020_s300_r_dummy2.stl"/>
      </geometry>
    </collision>
    <!-- Part j5_2 -->
    <visual>
      <origin xyz="-0.021 -0 -0.045" rpy="0 1.5708 0"/>
      <geometry>
        <mesh filename="package://rover_description/RescueRangersArmMeshes/j5.stl"/>
      </geometry>
      <material name="j5_2_material">
        <color rgba="0.615686 0.811765 0.929412 1"/>
      </material>
    </visual>
    <collision>
      <origin xyz="-0.021 -0 -0.045" rpy="0 1.5708 0"/>
      <geometry>
        <mesh filename="package://rover_description/RescueRangersArmMeshes/j5.stl"/>
      </geometry>
    </collision>
  </link>
  <!-- Link j3 -->
  <link name="j3">
    <inertial>
      <origin xyz="0 0 0" rpy="0 0 0"/>
      <mass value="1e-09"/>
      <inertia ixx="1e-09" ixy="0" ixz="0" iyy="1e-09" iyz="0" izz="1e-09"/>
    </inertial>
    <!-- Part j3 -->
    <visual>
      <origin xyz="0.021 0 0.00556714" rpy="0 -1.5708 0"/>
      <geometry>
        <mesh filename="package://rover_description/RescueRangersArmMeshes/j3.stl"/>
      </geometry>
      <material name="j3_material">
        <color rgba="0.615686 0.811765 0.929412 1"/>
      </material>
    </visual>
    <collision>
      <origin xyz="0.021 0 0.00556714" rpy="0 -1.5708 0"/>
      <geometry>
        <mesh filename="package://rover_description/RescueRangersArmMeshes/j3.stl"/>
      </geometry>
    </collision>
    <!-- Part h42p_020_s300_r_dummy2_3 -->
    <visual>
      <origin xyz="0 -0.021 -0.057" rpy="-1.5708 -1.5708 0"/>
      <geometry>
        <mesh filename="package://rover_description/RescueRangersArmMeshes/h42p_020_s300_r_dummy2.stl"/>
      </geometry>
      <material name="h42p_020_s300_r_dummy2_3_material">
        <color rgba="0.647059 0.647059 0.647059 1"/>
      </material>
    </visual>
    <collision>
      <origin xyz="0 -0.021 -0.057" rpy="-1.5708 -1.5708 0"/>
      <geometry>
        <mesh filename="package://rover_description/RescueRangersArmMeshes/h42p_020_s300_r_dummy2.stl"/>
      </geometry>
    </collision>
    <!-- Part imported1 -->
    <visual>
      <origin xyz="0.047 0 -0.0796285" rpy="-1.5708 -0 -1.5708"/>
      <geometry>
        <mesh filename="package://rover_description/RescueRangersArmMeshes/imported1.stl"/>
      </geometry>
      <material name="imported1_material">
        <color rgba="0.752941 0.752941 0.752941 1"/>
      </material>
    </visual>
    <collision>
      <origin xyz="0.047 0 -0.0796285" rpy="-1.5708 -0 -1.5708"/>
      <geometry>
        <mesh filename="package://rover_description/RescueRangersArmMeshes/imported1.stl"/>
      </geometry>
    </collision>
    <!-- Part imported1_2 -->
    <visual>
      <origin xyz="0.047 0 -0.0276285" rpy="1.5708 0 1.5708"/>
      <geometry>
        <mesh filename="package://rover_description/RescueRangersArmMeshes/imported1.stl"/>
      </geometry>
      <material name="imported1_2_material">
        <color rgba="0.752941 0.752941 0.752941 1"/>
      </material>
    </visual>
    <collision>
      <origin xyz="0.047 0 -0.0276285" rpy="1.5708 0 1.5708"/>
      <geometry>
        <mesh filename="package://rover_description/RescueRangersArmMeshes/imported1.stl"/>
      </geometry>
    </collision>
    <!-- Part motoratt2 -->
    <visual>
      <origin xyz="0.31548 0 -0.0539785" rpy="-0 1.5708 0"/>
      <geometry>
        <mesh filename="package://rover_description/RescueRangersArmMeshes/motoratt2.stl"/>
      </geometry>
      <material name="motoratt2_material">
        <color rgba="0.498039 0.498039 0.498039 1"/>
      </material>
    </visual>
    <collision>
      <origin xyz="0.31548 0 -0.0539785" rpy="-0 1.5708 0"/>
      <geometry>
        <mesh filename="package://rover_description/RescueRangersArmMeshes/motoratt2.stl"/>
      </geometry>
    </collision>
    <!-- Part armlink -->
    <visual>
      <origin xyz="0.377 0 -0.0536285" rpy="1.5708 -1.5708 0"/>
      <geometry>
        <mesh filename="package://rover_description/RescueRangersArmMeshes/armlink.stl"/>
      </geometry>
      <material name="armlink_material">
        <color rgba="0.498039 0.498039 0.498039 1"/>
      </material>
    </visual>
    <collision>
      <origin xyz="0.377 0 -0.0536285" rpy="1.5708 -1.5708 0"/>
      <geometry>
        <mesh filename="package://rover_description/RescueRangersArmMeshes/armlink.stl"/>
      </geometry>
    </collision>
  </link>
  <!-- Link h42p_020_s300_r_dummy2_2 -->
  <link name="h42p_020_s300_r_dummy2_2">
    <inertial>
      <origin xyz="0 0 0" rpy="0 0 0"/>
      <mass value="1e-09"/>
      <inertia ixx="1e-09" ixy="0" ixz="0" iyy="1e-09" iyz="0" izz="1e-09"/>
    </inertial>
    <!-- Part imported1_3 -->
    <visual>
      <origin xyz="0.0595 0 0.03605" rpy="0 0 -1.5708"/>
      <geometry>
        <mesh filename="package://rover_description/RescueRangersArmMeshes/imported1.stl"/>
      </geometry>
      <material name="imported1_3_material">
        <color rgba="0.752941 0.752941 0.752941 1"/>
      </material>
    </visual>
    <collision>
      <origin xyz="0.0595 0 0.03605" rpy="0 0 -1.5708"/>
      <geometry>
        <mesh filename="package://rover_description/RescueRangersArmMeshes/imported1.stl"/>
      </geometry>
    </collision>
    <!-- Part motoratt2_2 -->
    <visual>
      <origin xyz="0.45102 -0 0.0097" rpy="-0 -1.5708 0"/>
      <geometry>
        <mesh filename="package://rover_description/RescueRangersArmMeshes/motoratt2.stl"/>
      </geometry>
      <material name="motoratt2_2_material">
        <color rgba="0.498039 0.498039 0.498039 1"/>
      </material>
    </visual>
    <collision>
      <origin xyz="0.45102 -0 0.0097" rpy="-0 -1.5708 0"/>
      <geometry>
        <mesh filename="package://rover_description/RescueRangersArmMeshes/motoratt2.stl"/>
      </geometry>
    </collision>
    <!-- Part imported1_4 -->
    <visual>
      <origin xyz="0.0595 0 -0.01665" rpy="-1.5708 -0 -1.5708"/>
      <geometry>
        <mesh filename="package://rover_description/RescueRangersArmMeshes/imported1.stl"/>
      </geometry>
      <material name="imported1_4_material">
        <color rgba="0.752941 0.752941 0.752941 1"/>
      </material>
    </visual>
    <collision>
      <origin xyz="0.0595 0 -0.01665" rpy="-1.5708 -0 -1.5708"/>
      <geometry>
        <mesh filename="package://rover_description/RescueRangersArmMeshes/imported1.stl"/>
      </geometry>
    </collision>
    <!-- Part armlink_2 -->
    <visual>
      <origin xyz="0.3895 -0.06152 0.0097" rpy="-1.5708 1.5708 0"/>
      <geometry>
        <mesh filename="package://rover_description/RescueRangersArmMeshes/armlink__2.stl"/>
      </geometry>
      <material name="armlink_2_material">
        <color rgba="0.498039 0.498039 0.498039 1"/>
      </material>
    </visual>
    <collision>
      <origin xyz="0.3895 -0.06152 0.0097" rpy="-1.5708 1.5708 0"/>
      <geometry>
        <mesh filename="package://rover_description/RescueRangersArmMeshes/armlink__2.stl"/>
      </geometry>
    </collision>
    <!-- Part h42p_020_s300_r_dummy2_4 -->
    <visual>
      <origin xyz="0 0.021 -0.057" rpy="1.5708 1.5708 0"/>
      <geometry>
        <mesh filename="package://rover_description/RescueRangersArmMeshes/h42p_020_s300_r_dummy2__2.stl"/>
      </geometry>
      <material name="h42p_020_s300_r_dummy2_4_material">
        <color rgba="0.647059 0.647059 0.647059 1"/>
      </material>
    </visual>
    <collision>
      <origin xyz="0 0.021 -0.057" rpy="1.5708 1.5708 0"/>
      <geometry>
        <mesh filename="package://rover_description/RescueRangersArmMeshes/h42p_020_s300_r_dummy2__2.stl"/>
      </geometry>
    </collision>
    <!-- Part j3_2 -->
    <visual>
      <origin xyz="0.0335 0 0.0097" rpy="-3.14159 1.5708 0"/>
      <geometry>
        <mesh filename="package://rover_description/RescueRangersArmMeshes/j3__2.stl"/>
      </geometry>
      <material name="j3_2_material">
        <color rgba="0.615686 0.811765 0.929412 1"/>
      </material>
    </visual>
    <collision>
      <origin xyz="0.0335 0 0.0097" rpy="-3.14159 1.5708 0"/>
      <geometry>
        <mesh filename="package://rover_description/RescueRangersArmMeshes/j3__2.stl"/>
      </geometry>
    </collision>
  </link>
  <!-- Link part_5 -->
  <link name="part_5">
    <inertial>
      <origin xyz="0 0 0" rpy="0 0 0"/>
      <mass value="1e-09"/>
      <inertia ixx="1e-09" ixy="0" ixz="0" iyy="1e-09" iyz="0" izz="1e-09"/>
    </inertial>
    <!-- Part h42p_020_s300_r_dummy2_5 -->
    <visual>
      <origin xyz="0 0.021 -0.057" rpy="1.5708 1.5708 0"/>
      <geometry>
        <mesh filename="package://rover_description/RescueRangersArmMeshes/h42p_020_s300_r_dummy2__2.stl"/>
      </geometry>
      <material name="h42p_020_s300_r_dummy2_5_material">
        <color rgba="0.647059 0.647059 0.647059 1"/>
      </material>
    </visual>
    <collision>
      <origin xyz="0 0.021 -0.057" rpy="1.5708 1.5708 0"/>
      <geometry>
        <mesh filename="package://rover_description/RescueRangersArmMeshes/h42p_020_s300_r_dummy2__2.stl"/>
      </geometry>
    </collision>
    <!-- Part j2 -->
    <visual>
      <origin xyz="-0.0337 -0 0.0127" rpy="0 1.5708 0"/>
      <geometry>
        <mesh filename="package://rover_description/RescueRangersArmMeshes/j2.stl"/>
      </geometry>
      <material name="j2_material">
        <color rgba="0.615686 0.811765 0.929412 1"/>
      </material>
    </visual>
    <collision>
      <origin xyz="-0.0337 -0 0.0127" rpy="0 1.5708 0"/>
      <geometry>
        <mesh filename="package://rover_description/RescueRangersArmMeshes/j2.stl"/>
      </geometry>
    </collision>
    <!-- Part part_5 -->
    <visual>
      <origin xyz="-0.0337 -0 0.0127" rpy="0 1.5708 0"/>
      <geometry>
        <mesh filename="package://rover_description/RescueRangersArmMeshes/part_5.stl"/>
      </geometry>
      <material name="part_5_material">
        <color rgba="0.231373 0.380392 0.705882 1"/>
      </material>
    </visual>
    <collision>
      <origin xyz="-0.0337 -0 0.0127" rpy="0 1.5708 0"/>
      <geometry>
        <mesh filename="package://rover_description/RescueRangersArmMeshes/part_5.stl"/>
      </geometry>
    </collision>
    <!-- Part part_3 -->
    <visual>
      <origin xyz="-0.05657 -1.12e-05 0.0126944" rpy="0 1.5708 0"/>
      <geometry>
        <mesh filename="package://rover_description/RescueRangersArmMeshes/part_3.stl"/>
      </geometry>
      <material name="part_3_material">
        <color rgba="0.647059 0.647059 0.647059 1"/>
      </material>
    </visual>
    <collision>
      <origin xyz="-0.05657 -1.12e-05 0.0126944" rpy="0 1.5708 0"/>
      <geometry>
        <mesh filename="package://rover_description/RescueRangersArmMeshes/part_3.stl"/>
      </geometry>
    </collision>
  </link>
  <!-- Link part_5_2 -->
  <link name="part_5_2">
    <inertial>
      <origin xyz="0 0 0" rpy="0 0 0"/>
      <mass value="1e-09"/>
      <inertia ixx="1e-09" ixy="0" ixz="0" iyy="1e-09" iyz="0" izz="1e-09"/>
    </inertial>
    <!-- Part part_2 -->
    <visual>
      <origin xyz="-0 -0 -0.0095" rpy="0 -0 0"/>
      <geometry>
        <mesh filename="package://rover_description/RescueRangersArmMeshes/part_2.stl"/>
      </geometry>
      <material name="part_2_material">
        <color rgba="0.647059 0.647059 0.647059 1"/>
      </material>
    </visual>
    <collision>
      <origin xyz="-0 -0 -0.0095" rpy="0 -0 0"/>
      <geometry>
        <mesh filename="package://rover_description/RescueRangersArmMeshes/part_2.stl"/>
      </geometry>
    </collision>
    <!-- Part part_5_2 -->
    <visual>
      <origin xyz="-0 -0 -0.0095" rpy="0 -0 0"/>
      <geometry>
        <mesh filename="package://rover_description/RescueRangersArmMeshes/part_5__2.stl"/>
      </geometry>
      <material name="part_5_2_material">
        <color rgba="0.917647 0.917647 0.917647 1"/>
      </material>
    </visual>
    <collision>
      <origin xyz="-0 -0 -0.0095" rpy="0 -0 0"/>
      <geometry>
        <mesh filename="package://rover_description/RescueRangersArmMeshes/part_5__2.stl"/>
      </geometry>
    </collision>
    <!-- Part part_4 -->
    <visual>
      <origin xyz="-0 -0 -0.0095" rpy="0 -0 0"/>
      <geometry>
        <mesh filename="package://rover_description/RescueRangersArmMeshes/part_4.stl"/>
      </geometry>
      <material name="part_4_material">
        <color rgba="0.231373 0.380392 0.705882 1"/>
      </material>
    </visual>
    <collision>
      <origin xyz="-0 -0 -0.0095" rpy="0 -0 0"/>
      <geometry>
        <mesh filename="package://rover_description/RescueRangersArmMeshes/part_4.stl"/>
      </geometry>
    </collision>
    <!-- Part h42p_020_s300_r_dummy2_6 -->
    <visual>
      <origin xyz="-0 -0 -0.00802" rpy="0 -0 0"/>
      <geometry>
        <mesh filename="package://rover_description/RescueRangersArmMeshes/h42p_020_s300_r_dummy2__3.stl"/>
      </geometry>
      <material name="h42p_020_s300_r_dummy2_6_material">
        <color rgba="0.647059 0.647059 0.647059 1"/>
      </material>
    </visual>
    <collision>
      <origin xyz="-0 -0 -0.00802" rpy="0 -0 0"/>
      <geometry>
        <mesh filename="package://rover_description/RescueRangersArmMeshes/h42p_020_s300_r_dummy2__3.stl"/>
      </geometry>
    </collision>
  </link>
  <!-- Joint from part_5 to part_5_2 -->
  <joint name="j0_base" type="revolute">
    <origin xyz="-0.04605 -1.12e-05 0.0126944" rpy="0 1.5708 0"/>
    <parent link="part_5"/>
    <child link="part_5_2"/>
    <axis xyz="0 0 1"/>
    <limit effort="10" velocity="10" lower="-0.785398" upper="0.785398"/>
  </joint>
  <!-- Joint from h42p_020_s300_r_dummy2_2 to part_5 -->
  <joint name="j1" type="revolute">
    <origin xyz="0.3895 -0 -0.003" rpy="-0 -0 3.14159"/>
    <parent link="h42p_020_s300_r_dummy2_2"/>
    <child link="part_5"/>
    <axis xyz="0 0 1"/>
    <limit effort="10" velocity="10" lower="-1.5708" upper="1.5708"/>
  </joint>
  <!-- Joint from j3 to h42p_020_s300_r_dummy2_2 -->
  <joint name="j2" type="revolute">
    <origin xyz="0.377 0 -0.0412785" rpy="3.14159 -0 -0"/>
    <parent link="j3"/>
    <child link="h42p_020_s300_r_dummy2_2"/>
    <axis xyz="0 0 1"/>
    <limit effort="10" velocity="10" lower="-1.5708" upper="1.5708"/>
  </joint>
  <!-- Joint from h42p_020_s300_r_dummy2 to j3 -->
  <joint name="j3" type="revolute">
    <origin xyz="-0.027 -0 -0.045" rpy="0 1.5708 0"/>
    <parent link="h42p_020_s300_r_dummy2"/>
    <child link="j3"/>
    <axis xyz="0 0 1"/>
    <limit effort="10" velocity="10" lower="-3.14159" upper="3.14159"/>
  </joint>
  <!-- Joint from j5 to h42p_020_s300_r_dummy2 -->
  <joint name="j4" type="revolute">
    <origin xyz="0.0779729 1.12e-05 0.94353" rpy="-0 0 -0"/>
    <parent link="j5"/>
    <child link="h42p_020_s300_r_dummy2"/>
    <axis xyz="0 0 1"/>
    <limit effort="10" velocity="10" lower="-4.71239" upper="4.71239"/>
  </joint>
  <!-- Link frame -->
  <link name="frame">
    <inertial>
      <origin xyz="0 0 0" rpy="0 0 0"/>
      <mass value="1e-09"/>
      <inertia ixx="1e-09" ixy="0" ixz="0" iyy="1e-09" iyz="0" izz="1e-09"/>
    </inertial>
    <!-- Part frame -->
    <visual>
      <origin xyz="-0 -0 -0.055" rpy="-1.5708 0 -1.5708"/>
      <geometry>
        <mesh filename="package://rover_description/RescueRangersArmMeshes/frame.stl"/>
      </geometry>
      <material name="frame_material">
        <color rgba="0.698039 0 0 1"/>
      </material>
    </visual>
    <collision>
      <origin xyz="-0 -0 -0.055" rpy="-1.5708 0 -1.5708"/>
      <geometry>
        <mesh filename="package://rover_description/RescueRangersArmMeshes/frame.stl"/>
      </geometry>
    </collision>
    <!-- Part gripper_tpu -->
    <visual>
      <origin xyz="0.03915 0.0165996 -0.0547135" rpy="-1.5708 -0 1.5708"/>
      <geometry>
        <mesh filename="package://rover_description/RescueRangersArmMeshes/gripper_tpu.stl"/>
      </geometry>
      <material name="gripper_tpu_material">
        <color rgba="0.972549 0.529412 0.00392157 1"/>
      </material>
    </visual>
    <collision>
      <origin xyz="0.03915 0.0165996 -0.0547135" rpy="-1.5708 -0 1.5708"/>
      <geometry>
        <mesh filename="package://rover_description/RescueRangersArmMeshes/gripper_tpu.stl"/>
      </geometry>
    </collision>
    <!-- Part gripper_tpu_2 -->
    <visual>
      <origin xyz="-0.04665 -0.0165996 -0.0547135" rpy="-1.5708 0 -1.5708"/>
      <geometry>
        <mesh filename="package://rover_description/RescueRangersArmMeshes/gripper_tpu.stl"/>
      </geometry>
      <material name="gripper_tpu_2_material">
        <color rgba="0.972549 0.529412 0.00392157 1"/>
      </material>
    </visual>
    <collision>
      <origin xyz="-0.04665 -0.0165996 -0.0547135" rpy="-1.5708 0 -1.5708"/>
      <geometry>
        <mesh filename="package://rover_description/RescueRangersArmMeshes/gripper_tpu.stl"/>
      </geometry>
    </collision>
    <!-- Part blocco_dito -->
    <visual>
      <origin xyz="-0.00374999 -0.039 -0.0736" rpy="-1.5708 -0 1.5708"/>
      <geometry>
        <mesh filename="package://rover_description/RescueRangersArmMeshes/blocco_dito.stl"/>
      </geometry>
      <material name="blocco_dito_material">
        <color rgba="0.698039 0.698039 0.698039 1"/>
      </material>
    </visual>
    <collision>
      <origin xyz="-0.00374999 -0.039 -0.0736" rpy="-1.5708 -0 1.5708"/>
      <geometry>
        <mesh filename="package://rover_description/RescueRangersArmMeshes/blocco_dito.stl"/>
      </geometry>
    </collision>
    <!-- Part blocco_dito_mirror -->
    <visual>
      <origin xyz="-0.00374999 -0.031 -0.0736" rpy="-1.5708 -0 1.5708"/>
      <geometry>
        <mesh filename="package://rover_description/RescueRangersArmMeshes/blocco_dito_mirror.stl"/>
      </geometry>
      <material name="blocco_dito_mirror_material">
        <color rgba="0.698039 0.698039 0.698039 1"/>
      </material>
    </visual>
    <collision>
      <origin xyz="-0.00374999 -0.031 -0.0736" rpy="-1.5708 -0 1.5708"/>
      <geometry>
        <mesh filename="package://rover_description/RescueRangersArmMeshes/blocco_dito_mirror.stl"/>
      </geometry>
    </collision>
  </link>
  <!-- Joint from j5 to frame -->
  <joint name="j5" type="revolute">
    <origin xyz="0.122973 -2.79302e-05 0.97053" rpy="-3.14159 1.5708 0"/>
    <parent link="j5"/>
    <child link="frame"/>
    <axis xyz="0 0 1"/>
    <limit effort="10" velocity="10" lower="-3.141592653589793" upper="3.141592653589793"/>
  </joint>
</robot>
