<?xml version="1.0" ?>
<!-- Generated using onshape-to-robot -->
<!-- Onshape document_id: dccc9867c88f4c00ebd285c5 / workspace_id: 4d6b4b67b32ea734f124cf6d -->
<mujoco model="rover">
  <compiler angle="radian" meshdir="RescueRangersMeshes" autolimits="true"/>
  <default>
    <default class="rover">
      <joint frictionloss="0.1" armature="0.005"/>
      <position kp="50" dampratio="1"/>
      <default class="visual">
        <geom type="mesh" contype="0" conaffinity="0" group="2"/>
      </default>
      <default class="collision">
        <geom group="3"/>
      </default>
    </default>
  </default>
  <worldbody>
    <!-- Link chassisframe -->
    <body name="chassisframe" pos="0 0 0" quat="1 0 0 0" childclass="rover">
      <freejoint name="chassisframe_freejoint"/>
      <inertial pos="0.0192497 -0.207878 0.16114" mass="49.7337" fullinertia="2.52002 2.2653 3.03093 6.90051e-05 2.03164e-05 0.251277"/>
      <!-- Part base_motor_mount_plate -->
      <geom type="mesh" class="visual" pos="0.0192418 -0.256778 0.302761" quat="0 0 0 -1" mesh="base_motor_mount_plate" material="base_motor_mount_plate_material"/>
      <geom type="mesh" class="collision" pos="0.0192418 -0.256778 0.302761" quat="0 0 0 -1" mesh="base_motor_mount_plate" material="base_motor_mount_plate_material"/>
      <!-- Part gobildamount -->
      <geom type="mesh" class="visual" pos="0.298854 0.074844 -0.0944395" quat="0.5 -0.5 0.5 -0.5" mesh="gobildamount" material="gobildamount_material"/>
      <geom type="mesh" class="collision" pos="0.298854 0.074844 -0.0944395" quat="0.5 -0.5 0.5 -0.5" mesh="gobildamount" material="gobildamount_material"/>
      <!-- Part gobilda_motor -->
      <geom type="mesh" class="visual" pos="0.323854 0.074844 -0.0944395" quat="0.5 -0.5 0.5 -0.5" mesh="gobilda_motor" material="gobilda_motor_material"/>
      <geom type="mesh" class="collision" pos="0.323854 0.074844 -0.0944395" quat="0.5 -0.5 0.5 -0.5" mesh="gobilda_motor" material="gobilda_motor_material"/>
      <!-- Part gobilda_motor_2 -->
      <geom type="mesh" class="visual" pos="-0.285346 -0.382356 -0.0944395" quat="0.5 -0.5 -0.5 0.5" mesh="gobilda_motor" material="gobilda_motor_material"/>
      <geom type="mesh" class="collision" pos="-0.285346 -0.382356 -0.0944395" quat="0.5 -0.5 -0.5 0.5" mesh="gobilda_motor" material="gobilda_motor_material"/>
      <!-- Part framecover -->
      <geom type="mesh" class="visual" pos="0.019254 -0.1552 0.198411" quat="0 0.707107 0.707107 0" mesh="framecover" material="framecover_material"/>
      <geom type="mesh" class="collision" pos="0.019254 -0.1552 0.198411" quat="0 0.707107 0.707107 0" mesh="framecover" material="framecover_material"/>
      <!-- Part gobildamount_2 -->
      <geom type="mesh" class="visual" pos="0.298854 -0.382356 -0.0944395" quat="0.5 -0.5 0.5 -0.5" mesh="gobildamount" material="gobildamount_material"/>
      <geom type="mesh" class="collision" pos="0.298854 -0.382356 -0.0944395" quat="0.5 -0.5 0.5 -0.5" mesh="gobildamount" material="gobildamount_material"/>
      <!-- Part gobilda_motor_3 -->
      <geom type="mesh" class="visual" pos="-0.285346 0.074844 -0.0944395" quat="0.5 -0.5 -0.5 0.5" mesh="gobilda_motor" material="gobilda_motor_material"/>
      <geom type="mesh" class="collision" pos="-0.285346 0.074844 -0.0944395" quat="0.5 -0.5 -0.5 0.5" mesh="gobilda_motor" material="gobilda_motor_material"/>
      <!-- Part chassisframe -->
      <geom type="mesh" class="visual" pos="0.019254 -0.1552 -0.0555895" quat="0.707107 0 0 0.707107" mesh="chassisframe" material="chassisframe_material"/>
      <geom type="mesh" class="collision" pos="0.019254 -0.1552 -0.0555895" quat="0.707107 0 0 0.707107" mesh="chassisframe" material="chassisframe_material"/>
      <!-- Part h42p_020_s300_r_dummy2 -->
      <geom type="mesh" class="visual" pos="0.0192418 -0.256778 0.302761" quat="0 0 -0 -1" mesh="h42p_020_s300_r_dummy2" material="h42p_020_s300_r_dummy2_material"/>
      <geom type="mesh" class="collision" pos="0.0192418 -0.256778 0.302761" quat="0 0 -0 -1" mesh="h42p_020_s300_r_dummy2" material="h42p_020_s300_r_dummy2_material"/>
      <!-- Part framecover_2 -->
      <geom type="mesh" class="visual" pos="0.019254 -0.1552 -0.0555895" quat="0.707107 0 0 0.707107" mesh="framecover" material="framecover_material"/>
      <geom type="mesh" class="collision" pos="0.019254 -0.1552 -0.0555895" quat="0.707107 0 0 0.707107" mesh="framecover" material="framecover_material"/>
      <!-- Part base_tower -->
      <geom type="mesh" class="visual" pos="0.019254 -0.2568 0.302761" quat="0 0 0 -1" mesh="base_tower" material="base_tower_material"/>
      <geom type="mesh" class="collision" pos="0.019254 -0.2568 0.302761" quat="0 0 0 -1" mesh="base_tower" material="base_tower_material"/>
      <!-- Part gobildamount_3 -->
      <geom type="mesh" class="visual" pos="-0.260346 -0.382356 -0.0944395" quat="0.5 -0.5 -0.5 0.5" mesh="gobildamount" material="gobildamount_material"/>
      <geom type="mesh" class="collision" pos="-0.260346 -0.382356 -0.0944395" quat="0.5 -0.5 -0.5 0.5" mesh="gobildamount" material="gobildamount_material"/>
      <!-- Part gobildamount_4 -->
      <geom type="mesh" class="visual" pos="-0.260346 0.074844 -0.0944395" quat="0.5 -0.5 -0.5 0.5" mesh="gobildamount" material="gobildamount_material"/>
      <geom type="mesh" class="collision" pos="-0.260346 0.074844 -0.0944395" quat="0.5 -0.5 -0.5 0.5" mesh="gobildamount" material="gobildamount_material"/>
      <!-- Part gobilda_motor_4 -->
      <geom type="mesh" class="visual" pos="0.323854 -0.382356 -0.0944395" quat="0.5 -0.5 0.5 -0.5" mesh="gobilda_motor" material="gobilda_motor_material"/>
      <geom type="mesh" class="collision" pos="0.323854 -0.382356 -0.0944395" quat="0.5 -0.5 0.5 -0.5" mesh="gobilda_motor" material="gobilda_motor_material"/>
      <!-- Link gobilda_shaft -->
      <body name="gobilda_shaft" pos="0.323854 0.074844 -0.0944395" quat="0.5 -0.5 -0.5 0.5">
        <!-- Joint from chassisframe to gobilda_shaft -->
        <joint axis="0 0 1" name="FR" type="hinge"/>
        <inertial pos="4.88834e-06 -2.42413e-05 -0.0439111" mass="0.91212" fullinertia="0.00370902 0.00370902 0.00614069 1e-12 1.54e-10 -7.65e-10"/>
        <!-- Part gobilda_shaft -->
        <geom type="mesh" class="visual" pos="0 -0 -0.0815" quat="1 -0 0 0" mesh="gobilda_shaft" material="gobilda_shaft_material"/>
        <geom type="mesh" class="collision" pos="0 -0 -0.0815" quat="1 -0 0 0" mesh="gobilda_shaft" material="gobilda_shaft_material"/>
        <!-- Part urc_rover_wheel -->
        <geom type="mesh" class="visual" pos="4.94187e-06 -2.45067e-05 -0.00825" quat="0 0.812078 0.583548 0" mesh="urc_rover_wheel" material="urc_rover_wheel_material"/>
        <geom type="mesh" class="collision" pos="4.94187e-06 -2.45067e-05 -0.00825" quat="0 0.812078 0.583548 0" mesh="urc_rover_wheel" material="urc_rover_wheel_material"/>
      </body>
      <!-- Link gobilda_shaft_2 -->
      <body name="gobilda_shaft_2" pos="0.323854 -0.382356 -0.0944395" quat="0.5 -0.5 -0.5 0.5">
        <!-- Joint from chassisframe to gobilda_shaft_2 -->
        <joint axis="0 0 1" name="BR" type="hinge"/>
        <inertial pos="2.34377e-05 -7.8872e-06 -0.0439111" mass="0.91212" fullinertia="0.00370902 0.00370902 0.00614069 2e-12 7.4e-10 -2.49e-10"/>
        <!-- Part gobilda_shaft_2 -->
        <geom type="mesh" class="visual" pos="0 -0 -0.0815" quat="1 -0 0 0" mesh="gobilda_shaft" material="gobilda_shaft_material"/>
        <geom type="mesh" class="collision" pos="0 -0 -0.0815" quat="1 -0 0 0" mesh="gobilda_shaft" material="gobilda_shaft_material"/>
        <!-- Part urc_rover_wheel_2 -->
        <geom type="mesh" class="visual" pos="2.36944e-05 -7.97357e-06 -0.00825" quat="0 -0.411506 -0.911407 -0" mesh="urc_rover_wheel" material="urc_rover_wheel_material"/>
        <geom type="mesh" class="collision" pos="2.36944e-05 -7.97357e-06 -0.00825" quat="0 -0.411506 -0.911407 -0" mesh="urc_rover_wheel" material="urc_rover_wheel_material"/>
      </body>
      <!-- Link gobilda_shaft_3 -->
      <body name="gobilda_shaft_3" pos="-0.285346 -0.382356 -0.0944395" quat="0.621881 -0.336547 0.621881 -0.336547">
        <!-- Joint from chassisframe to gobilda_shaft_3 -->
        <joint axis="0 0 1" name="BL" type="hinge"/>
        <inertial pos="4.88834e-06 -2.42413e-05 -0.0439111" mass="0.91212" fullinertia="0.00370902 0.00370902 0.00614069 1e-12 1.54e-10 -7.65e-10"/>
        <!-- Part gobilda_shaft_3 -->
        <geom type="mesh" class="visual" pos="0 0 -0.0815" quat="1 -0 0 -0" mesh="gobilda_shaft" material="gobilda_shaft_material"/>
        <geom type="mesh" class="collision" pos="0 0 -0.0815" quat="1 -0 0 -0" mesh="gobilda_shaft" material="gobilda_shaft_material"/>
        <!-- Part urc_rover_wheel_3 -->
        <geom type="mesh" class="visual" pos="4.94187e-06 -2.45067e-05 -0.00825" quat="0 -0.0993285 0.995055 -0" mesh="urc_rover_wheel" material="urc_rover_wheel_material"/>
        <geom type="mesh" class="collision" pos="4.94187e-06 -2.45067e-05 -0.00825" quat="0 -0.0993285 0.995055 -0" mesh="urc_rover_wheel" material="urc_rover_wheel_material"/>
      </body>
      <!-- Link gobilda_shaft_4 -->
      <body name="gobilda_shaft_4" pos="-0.285346 0.074844 -0.0944395" quat="0.621881 -0.336547 0.621881 -0.336547">
        <!-- Joint from chassisframe to gobilda_shaft_4 -->
        <joint axis="0 0 1" name="FL" type="hinge"/>
        <inertial pos="4.88834e-06 -2.42413e-05 -0.0439111" mass="0.91212" fullinertia="0.00370902 0.00370902 0.00614069 1e-12 1.54e-10 -7.65e-10"/>
        <!-- Part gobilda_shaft_4 -->
        <geom type="mesh" class="visual" pos="0 0 -0.0815" quat="1 -0 0 -0" mesh="gobilda_shaft" material="gobilda_shaft_material"/>
        <geom type="mesh" class="collision" pos="0 0 -0.0815" quat="1 -0 0 -0" mesh="gobilda_shaft" material="gobilda_shaft_material"/>
        <!-- Part urc_rover_wheel_4 -->
        <geom type="mesh" class="visual" pos="4.94187e-06 -2.45067e-05 -0.00825" quat="0 0.583548 -0.812078 0" mesh="urc_rover_wheel" material="urc_rover_wheel_material"/>
        <geom type="mesh" class="collision" pos="4.94187e-06 -2.45067e-05 -0.00825" quat="0 0.583548 -0.812078 0" mesh="urc_rover_wheel" material="urc_rover_wheel_material"/>
      </body>
      <!-- Link h42p_020_s300_r_dummy2 -->
      <body name="h42p_020_s300_r_dummy2" pos="0.0192418 -0.256778 0.299761" quat="0 -0 1 0">
        <!-- Joint from chassisframe to h42p_020_s300_r_dummy2 -->
        <joint axis="0 0 1" name="arm_base" type="hinge"/>
        <inertial pos="-0.000125373 -0.0046229 -0.0295593" mass="9.43706" fullinertia="0.0616389 0.0663263 0.120154 -2.88562e-05 -6.50031e-05 -0.00168034"/>
        <!-- Part h42p_020_s300_r_dummy2_2 -->
        <geom type="mesh" class="visual" pos="-0.0028 0.041 -0.0195" quat="0 -1 0 -0" mesh="h42p_020_s300_r_dummy2__2" material="h42p_020_s300_r_dummy2__2_material"/>
        <geom type="mesh" class="collision" pos="-0.0028 0.041 -0.0195" quat="0 -1 0 -0" mesh="h42p_020_s300_r_dummy2__2" material="h42p_020_s300_r_dummy2__2_material"/>
        <!-- Part base_motor_link_plate -->
        <geom type="mesh" class="visual" pos="0 0 -0.003" quat="0 1 0 0" mesh="base_motor_link_plate" material="base_motor_link_plate_material"/>
        <geom type="mesh" class="collision" pos="0 0 -0.003" quat="0 1 0 0" mesh="base_motor_link_plate" material="base_motor_link_plate_material"/>
        <!-- Part lazy_suzan_outer_ring -->
        <geom type="mesh" class="visual" pos="0 0 -0.008" quat="0 1 0 0" mesh="lazy_suzan_outer_ring" material="lazy_suzan_outer_ring_material"/>
        <geom type="mesh" class="collision" pos="0 0 -0.008" quat="0 1 0 0" mesh="lazy_suzan_outer_ring" material="lazy_suzan_outer_ring_material"/>
        <!-- Part motoralignmentplate -->
        <geom type="mesh" class="visual" pos="-0 0.041 -0.0195" quat="0 1 0 0" mesh="motoralignmentplate" material="motoralignmentplate_material"/>
        <geom type="mesh" class="collision" pos="-0 0.041 -0.0195" quat="0 1 0 0" mesh="motoralignmentplate" material="motoralignmentplate_material"/>
        <!-- Part lazy_suzan_part -->
        <geom type="mesh" class="visual" pos="0 0 -0.008" quat="0 1 0 0" mesh="lazy_suzan_part" material="lazy_suzan_part_material"/>
        <geom type="mesh" class="collision" pos="0 0 -0.008" quat="0 1 0 0" mesh="lazy_suzan_part" material="lazy_suzan_part_material"/>
        <!-- Part base_upper_plate -->
        <geom type="mesh" class="visual" pos="0 0 -0.008" quat="0 1 0 0" mesh="base_upper_plate" material="base_upper_plate_material"/>
        <geom type="mesh" class="collision" pos="0 0 -0.008" quat="0 1 0 0" mesh="base_upper_plate" material="base_upper_plate_material"/>
        <!-- Part h42p_020_s300_r_dummy2_3 -->
        <geom type="mesh" class="visual" pos="-0.00045 0.041 -0.0195" quat="0 -1 0 -0" mesh="h42p_020_s300_r_dummy2__3" material="h42p_020_s300_r_dummy2__3_material"/>
        <geom type="mesh" class="collision" pos="-0.00045 0.041 -0.0195" quat="0 -1 0 -0" mesh="h42p_020_s300_r_dummy2__3" material="h42p_020_s300_r_dummy2__3_material"/>
        <!-- Link armlink -->
        <body name="armlink" pos="0.01225 -0.029 -0.0845" quat="0.5 -0.5 0.5 -0.5">
          <!-- Joint from h42p_020_s300_r_dummy2 to armlink -->
          <joint axis="0 0 1" name="arm_l0" type="hinge"/>
          <inertial pos="0.358569 4.4136e-06 -0.0175716" mass="2.02043" fullinertia="0.00669351 0.045651 0.0398258 3.9382e-06 0.000673965 1.3183e-08"/>
          <!-- Part generic_bracket -->
          <geom type="mesh" class="visual" pos="-0.07 -0.065 -0.0127" quat="0.5 -0.5 -0.5 -0.5" mesh="generic_bracket" material="generic_bracket_material"/>
          <geom type="mesh" class="collision" pos="-0.07 -0.065 -0.0127" quat="0.5 -0.5 -0.5 -0.5" mesh="generic_bracket" material="generic_bracket_material"/>
          <!-- Part armlink -->
          <geom type="mesh" class="visual" pos="-0.07 -0.065 -0.0127" quat="0.5 -0.5 -0.5 -0.5" mesh="armlink" material="armlink_material"/>
          <geom type="mesh" class="collision" pos="-0.07 -0.065 -0.0127" quat="0.5 -0.5 -0.5 -0.5" mesh="armlink" material="armlink_material"/>
          <!-- Part motoratt2 -->
          <geom type="mesh" class="visual" pos="-0.07 -0.065 -0.0127" quat="0.5 -0.5 -0.5 -0.5" mesh="motoratt2" material="motoratt2_material"/>
          <geom type="mesh" class="collision" pos="-0.07 -0.065 -0.0127" quat="0.5 -0.5 -0.5 -0.5" mesh="motoratt2" material="motoratt2_material"/>
          <!-- Part h42p_020_s300_r_dummy2_4 -->
          <geom type="mesh" class="visual" pos="-0.07 -0.065 -0.01755" quat="0.5 -0.5 -0.5 -0.5" mesh="h42p_020_s300_r_dummy2__4" material="h42p_020_s300_r_dummy2__4_material"/>
          <geom type="mesh" class="collision" pos="-0.07 -0.065 -0.01755" quat="0.5 -0.5 -0.5 -0.5" mesh="h42p_020_s300_r_dummy2__4" material="h42p_020_s300_r_dummy2__4_material"/>
          <!-- Part h42p_020_s300_r_dummy2_5 -->
          <geom type="mesh" class="visual" pos="-0.07 -0.065 -0.02055" quat="0.5 -0.5 -0.5 -0.5" mesh="h42p_020_s300_r_dummy2__5" material="h42p_020_s300_r_dummy2__5_material"/>
          <geom type="mesh" class="collision" pos="-0.07 -0.065 -0.02055" quat="0.5 -0.5 -0.5 -0.5" mesh="h42p_020_s300_r_dummy2__5" material="h42p_020_s300_r_dummy2__5_material"/>
          <!-- Part motorattachment -->
          <geom type="mesh" class="visual" pos="-0.07 -0.065 -0.0127" quat="0.5 -0.5 -0.5 -0.5" mesh="motorattachment" material="motorattachment_material"/>
          <geom type="mesh" class="collision" pos="-0.07 -0.065 -0.0127" quat="0.5 -0.5 -0.5 -0.5" mesh="motorattachment" material="motorattachment_material"/>
          <!-- Part l0_to_l1_mount -->
          <geom type="mesh" class="visual" pos="-0.07 -0.065 -0.01905" quat="0.5 -0.5 -0.5 -0.5" mesh="l0_to_l1_mount" material="l0_to_l1_mount_material"/>
          <geom type="mesh" class="collision" pos="-0.07 -0.065 -0.01905" quat="0.5 -0.5 -0.5 -0.5" mesh="l0_to_l1_mount" material="l0_to_l1_mount_material"/>
          <!-- Link armlink_2 -->
          <body name="armlink_2" pos="0.4445 -0 -0.00355" quat="1 0 0 -0">
            <!-- Joint from armlink to armlink_2 -->
            <joint axis="0 0 1" name="arm_l1" type="hinge"/>
            <inertial pos="-1.5e-11 0.150124 -0.0361387" mass="0.87849" fullinertia="0.00789692 0.000792499 0.00751794 1.77808e-06 -1e-12 0.0012604"/>
            <!-- Part h42p_020_s300_r_dummy2_6 -->
            <geom type="mesh" class="visual" pos="-0.5145 -0.0653 -0.001" quat="0.5 -0.5 -0.5 -0.5" mesh="h42p_020_s300_r_dummy2__6" material="h42p_020_s300_r_dummy2__6_material"/>
            <geom type="mesh" class="collision" pos="-0.5145 -0.0653 -0.001" quat="0.5 -0.5 -0.5 -0.5" mesh="h42p_020_s300_r_dummy2__6" material="h42p_020_s300_r_dummy2__6_material"/>
            <!-- Part armlink_2 -->
            <geom type="mesh" class="visual" pos="-0.5145 -0.065 -0.014" quat="0.5 -0.5 -0.5 -0.5" mesh="armlink__2" material="armlink__2_material"/>
            <geom type="mesh" class="collision" pos="-0.5145 -0.065 -0.014" quat="0.5 -0.5 -0.5 -0.5" mesh="armlink__2" material="armlink__2_material"/>
            <!-- Part motor_mount_bracket -->
            <geom type="mesh" class="visual" pos="-0.5145 -0.065 -0.014" quat="0.5 -0.5 -0.5 -0.5" mesh="motor_mount_bracket" material="motor_mount_bracket_material"/>
            <geom type="mesh" class="collision" pos="-0.5145 -0.065 -0.014" quat="0.5 -0.5 -0.5 -0.5" mesh="motor_mount_bracket" material="motor_mount_bracket_material"/>
            <!-- Part generic_bracket_2 -->
            <geom type="mesh" class="visual" pos="-0.5145 -0.065 -0.014" quat="0.5 -0.5 -0.5 -0.5" mesh="generic_bracket_2" material="generic_bracket_2_material"/>
            <geom type="mesh" class="collision" pos="-0.5145 -0.065 -0.014" quat="0.5 -0.5 -0.5 -0.5" mesh="generic_bracket_2" material="generic_bracket_2_material"/>
            <!-- Part motorattachment_2 -->
            <geom type="mesh" class="visual" pos="-0.5145 -0.065 -0.014" quat="0.5 -0.5 -0.5 -0.5" mesh="motorattachment__2" material="motorattachment__2_material"/>
            <geom type="mesh" class="collision" pos="-0.5145 -0.065 -0.014" quat="0.5 -0.5 -0.5 -0.5" mesh="motorattachment__2" material="motorattachment__2_material"/>
            <!-- Part motoratt2_2 -->
            <geom type="mesh" class="visual" pos="-0.5145 -0.065 -0.014" quat="0.5 -0.5 -0.5 -0.5" mesh="motoratt2__2" material="motoratt2__2_material"/>
            <geom type="mesh" class="collision" pos="-0.5145 -0.065 -0.014" quat="0.5 -0.5 -0.5 -0.5" mesh="motoratt2__2" material="motoratt2__2_material"/>
            <!-- Link h42p_020_s300_r_dummy2_2 -->
            <body name="h42p_020_s300_r_dummy2_2" pos="-0 0.2202 -0.096" quat="1 -0 0 0">
              <!-- Joint from armlink_2 to h42p_020_s300_r_dummy2_2 -->
              <joint axis="0 0 1" name="arm_l2" type="hinge"/>
              <inertial pos="0.0486071 8.2779e-06 -0.0267062" mass="0.538625" fullinertia="0.000240329 0.000740157 0.000709358 -8.441e-09 0.000153296 3.8547e-08"/>
              <!-- Part l2_plate -->
              <geom type="mesh" class="visual" pos="-0.5145 -0.2855 0.095" quat="0.5 -0.5 -0.5 -0.5" mesh="l2_plate" material="l2_plate_material"/>
              <geom type="mesh" class="collision" pos="-0.5145 -0.2855 0.095" quat="0.5 -0.5 -0.5 -0.5" mesh="l2_plate" material="l2_plate_material"/>
              <!-- Part h42p_020_s300_r_dummy2_7 -->
              <geom type="mesh" class="visual" pos="-0.489984 -0.2855 0.095" quat="0.5 -0.5 -0.5 -0.5" mesh="h42p_020_s300_r_dummy2__7" material="h42p_020_s300_r_dummy2__7_material"/>
              <geom type="mesh" class="collision" pos="-0.489984 -0.2855 0.095" quat="0.5 -0.5 -0.5 -0.5" mesh="h42p_020_s300_r_dummy2__7" material="h42p_020_s300_r_dummy2__7_material"/>
              <!-- Part motoratt2_3 -->
              <geom type="mesh" class="visual" pos="-0.5145 -0.2855 0.095" quat="0.5 -0.5 -0.5 -0.5" mesh="motoratt2__3" material="motoratt2__3_material"/>
              <geom type="mesh" class="collision" pos="-0.5145 -0.2855 0.095" quat="0.5 -0.5 -0.5 -0.5" mesh="motoratt2__3" material="motoratt2__3_material"/>
              <!-- Link part_1 -->
              <body name="part_1" pos="0.108 0 -0.03535" quat="0 0.707107 0 -0.707107">
                <!-- Joint from h42p_020_s300_r_dummy2_2 to part_1 -->
                <joint axis="0 0 1" name="arm_ee" type="hinge"/>
                <inertial pos="0 0 -0.0175" mass="0.804633" fullinertia="0.00157862 0.00157862 0.00299317 0 -0 0"/>
                <!-- Part part_1 -->
                <geom type="mesh" class="visual" pos="0 0 -0.0175" quat="0.707107 -0.707107 0 0" mesh="part_1" material="part_1_material"/>
                <geom type="mesh" class="collision" pos="0 0 -0.0175" quat="0.707107 -0.707107 0 0" mesh="part_1" material="part_1_material"/>
              </body>
            </body>
          </body>
        </body>
      </body>
    </body>
  </worldbody>
  <asset>
    <mesh file="motor_mount_bracket.stl"/>
    <mesh file="part_1.stl"/>
    <mesh file="motoralignmentplate.stl"/>
    <mesh file="generic_bracket.stl"/>
    <mesh file="armlink__2.stl"/>
    <mesh file="gobilda_shaft.stl"/>
    <mesh file="l2_plate.stl"/>
    <mesh file="h42p_020_s300_r_dummy2__2.stl"/>
    <mesh file="gobilda_motor.stl"/>
    <mesh file="motoratt2.stl"/>
    <mesh file="h42p_020_s300_r_dummy2__4.stl"/>
    <mesh file="l0_to_l1_mount.stl"/>
    <mesh file="chassisframe.stl"/>
    <mesh file="h42p_020_s300_r_dummy2.stl"/>
    <mesh file="h42p_020_s300_r_dummy2__3.stl"/>
    <mesh file="base_tower.stl"/>
    <mesh file="motorattachment__2.stl"/>
    <mesh file="h42p_020_s300_r_dummy2__6.stl"/>
    <mesh file="h42p_020_s300_r_dummy2__7.stl"/>
    <mesh file="motoratt2__3.stl"/>
    <mesh file="lazy_suzan_outer_ring.stl"/>
    <mesh file="lazy_suzan_part.stl"/>
    <mesh file="motoratt2__2.stl"/>
    <mesh file="base_upper_plate.stl"/>
    <mesh file="h42p_020_s300_r_dummy2__5.stl"/>
    <mesh file="urc_rover_wheel.stl"/>
    <mesh file="base_motor_link_plate.stl"/>
    <mesh file="base_motor_mount_plate.stl"/>
    <mesh file="motorattachment.stl"/>
    <mesh file="framecover.stl"/>
    <mesh file="generic_bracket_2.stl"/>
    <mesh file="gobildamount.stl"/>
    <mesh file="armlink.stl"/>
    <material name="base_motor_mount_plate_material" rgba="0.917647 0.917647 0.917647 1"/>
    <material name="gobildamount_material" rgba="0.901961 0.878431 0.811765 1"/>
    <material name="gobilda_motor_material" rgba="0.980392 0.713725 0.00392157 1"/>
    <material name="framecover_material" rgba="0.647059 0.647059 0.647059 1"/>
    <material name="chassisframe_material" rgba="0.811765 0.858824 0.898039 1"/>
    <material name="h42p_020_s300_r_dummy2_material" rgba="0.301961 0.290196 0.262745 1"/>
    <material name="base_tower_material" rgba="0.231373 0.380392 0.705882 1"/>
    <material name="gobilda_shaft_material" rgba="0.4 0.4 0.4 1"/>
    <material name="urc_rover_wheel_material" rgba="0.301961 0.301961 0.301961 1"/>
    <material name="h42p_020_s300_r_dummy2__2_material" rgba="0.301961 0.290196 0.262745 1"/>
    <material name="base_motor_link_plate_material" rgba="0.768627 0.886275 0.952941 1"/>
    <material name="lazy_suzan_outer_ring_material" rgba="0.615686 0.811765 0.929412 1"/>
    <material name="motoralignmentplate_material" rgba="0.901961 0.878431 0.811765 1"/>
    <material name="lazy_suzan_part_material" rgba="0.647059 0.647059 0.647059 1"/>
    <material name="base_upper_plate_material" rgba="0.972549 0.529412 0.00392157 1"/>
    <material name="h42p_020_s300_r_dummy2__3_material" rgba="0.301961 0.290196 0.262745 1"/>
    <material name="generic_bracket_material" rgba="0.901961 0.878431 0.811765 1"/>
    <material name="armlink_material" rgba="0.901961 0.878431 0.811765 1"/>
    <material name="motoratt2_material" rgba="0.901961 0.878431 0.811765 1"/>
    <material name="h42p_020_s300_r_dummy2__4_material" rgba="0.301961 0.290196 0.262745 1"/>
    <material name="h42p_020_s300_r_dummy2__5_material" rgba="0.301961 0.290196 0.262745 1"/>
    <material name="motorattachment_material" rgba="0.901961 0.878431 0.811765 1"/>
    <material name="l0_to_l1_mount_material" rgba="0.901961 0.878431 0.811765 1"/>
    <material name="h42p_020_s300_r_dummy2__6_material" rgba="0.301961 0.290196 0.262745 1"/>
    <material name="armlink__2_material" rgba="0.901961 0.878431 0.811765 1"/>
    <material name="motor_mount_bracket_material" rgba="0.901961 0.878431 0.811765 1"/>
    <material name="generic_bracket_2_material" rgba="0.901961 0.878431 0.811765 1"/>
    <material name="motorattachment__2_material" rgba="0.901961 0.878431 0.811765 1"/>
    <material name="motoratt2__2_material" rgba="0.901961 0.878431 0.811765 1"/>
    <material name="l2_plate_material" rgba="0.901961 0.878431 0.811765 1"/>
    <material name="h42p_020_s300_r_dummy2__7_material" rgba="0.301961 0.290196 0.262745 1"/>
    <material name="motoratt2__3_material" rgba="0.901961 0.878431 0.811765 1"/>
    <material name="part_1_material" rgba="0.764706 0.545098 0.803922 1"/>
  </asset>
  <actuator>
    <position class="rover" name="FR" joint="FR"/>
    <position class="rover" name="BR" joint="BR"/>
    <position class="rover" name="BL" joint="BL"/>
    <position class="rover" name="FL" joint="FL"/>
    <position class="rover" name="arm_base" joint="arm_base"/>
    <position class="rover" name="arm_l0" joint="arm_l0"/>
    <position class="rover" name="arm_l1" joint="arm_l1"/>
    <position class="rover" name="arm_l2" joint="arm_l2"/>
    <position class="rover" name="arm_ee" joint="arm_ee"/>
  </actuator>
  <equality/>
</mujoco>
