<?xml version="1.0" ?>
<!-- Generated using onshape-to-robot -->
<!-- Onshape document_id: b6ac805677604f50f29b90bd / workspace_id: f7cf7502a4385f463da6ef04 -->
<robot name="rover">
  <!-- Link chassis -->
  <link name="chassis">
    <inertial>
      <origin xyz="-0.266784 -0.20623 -0.0288184" rpy="0 0 0"/>
      <mass value="29.5784"/>
      <inertia ixx="0.731528" ixy="1.7327e-08" ixz="-0.096069" iyy="1.27479" iyz="1.2884e-08" izz="1.49519"/>
    </inertial>
    <!-- Part base -->
    <visual>
      <origin xyz="-0.113729 -0.20623 0.051442" rpy="-4.1366e-08 3.05199e-07 -3.9209e-08"/>
      <geometry>
        <mesh filename="package://rover_description/meshes/base.stl"/>
      </geometry>
      <material name="base_material">
        <color rgba="0.8 0.776471 0.713725 1"/>
      </material>
    </visual>
    <collision>
      <origin xyz="-0.113729 -0.20623 0.051442" rpy="-4.1366e-08 3.05199e-07 -3.9209e-08"/>
      <geometry>
        <mesh filename="package://rover_description/meshes/base.stl"/>
      </geometry>
    </collision>
    <!-- Part chassis -->
    <visual>
      <origin xyz="-0.266129 -0.20623 -0.151758" rpy="-4.1366e-08 3.05199e-07 -3.9209e-08"/>
      <geometry>
        <mesh filename="package://rover_description/meshes/chassis.stl"/>
      </geometry>
      <material name="chassis_material">
        <color rgba="0.811765 0.858824 0.898039 1"/>
      </material>
    </visual>
    <collision>
      <origin xyz="-0.266129 -0.20623 -0.151758" rpy="-4.1366e-08 3.05199e-07 -3.9209e-08"/>
      <geometry>
        <mesh filename="package://rover_description/meshes/chassis.stl"/>
      </geometry>
    </collision>
  </link>
  <!-- Link part_1 -->
  <link name="part_1">
    <inertial>
      <origin xyz="-0 0 -0.0475496" rpy="0 0 0"/>
      <mass value="5.36566"/>
      <inertia ixx="0.0699654" ixy="-0" ixz="0" iyy="0.0699654" iyz="-0" izz="0.12389"/>
    </inertial>
    <!-- Part part_1 -->
    <visual>
      <origin xyz="-0 0 0" rpy="-3.14159 0 -0"/>
      <geometry>
        <mesh filename="package://rover_description/meshes/part_1.stl"/>
      </geometry>
      <material name="part_1_material">
        <color rgba="0.4 0.4 0.4 1"/>
      </material>
    </visual>
    <collision>
      <origin xyz="-0 0 0" rpy="-3.14159 0 -0"/>
      <geometry>
        <mesh filename="package://rover_description/meshes/part_1.stl"/>
      </geometry>
    </collision>
  </link>
  <!-- Joint from chassis to part_1 -->
  <joint name="FL_drive" type="revolute">
    <origin xyz="-0.494729 -0.39673 -0.100958" rpy="-1.5708 3.05199e-07 -3.9209e-08"/>
    <parent link="chassis"/>
    <child link="part_1"/>
    <axis xyz="0 0 1"/>
    <limit effort="10" velocity="10" lower="-3.141592653589793" upper="3.141592653589793"/>
  </joint>
  <!-- Link part_1_2 -->
  <link name="part_1_2">
    <inertial>
      <origin xyz="-0 -0 -0.0475496" rpy="0 0 0"/>
      <mass value="5.36566"/>
      <inertia ixx="0.0699654" ixy="-0" ixz="0" iyy="0.0699654" iyz="-0" izz="0.12389"/>
    </inertial>
    <!-- Part part_1_2 -->
    <visual>
      <origin xyz="0 0 -0" rpy="3.14159 -0 0"/>
      <geometry>
        <mesh filename="package://rover_description/meshes/part_1.stl"/>
      </geometry>
      <material name="part_1_2_material">
        <color rgba="0.4 0.4 0.4 1"/>
      </material>
    </visual>
    <collision>
      <origin xyz="0 0 -0" rpy="3.14159 -0 0"/>
      <geometry>
        <mesh filename="package://rover_description/meshes/part_1.stl"/>
      </geometry>
    </collision>
  </link>
  <!-- Joint from chassis to part_1_2 -->
  <joint name="BL_drive" type="revolute">
    <origin xyz="-0.0375289 -0.39673 -0.100958" rpy="-1.5708 3.05199e-07 -3.9209e-08"/>
    <parent link="chassis"/>
    <child link="part_1_2"/>
    <axis xyz="0 0 1"/>
    <limit effort="10" velocity="10" lower="-3.141592653589793" upper="3.141592653589793"/>
  </joint>
  <!-- Link part_1_3 -->
  <link name="part_1_3">
    <inertial>
      <origin xyz="0 -0 -0.0475496" rpy="0 0 0"/>
      <mass value="5.36566"/>
      <inertia ixx="0.0699654" ixy="0" ixz="-0" iyy="0.0699654" iyz="-0" izz="0.12389"/>
    </inertial>
    <!-- Part part_1_3 -->
    <visual>
      <origin xyz="0 -0 -0" rpy="-3.14159 -0 -0"/>
      <geometry>
        <mesh filename="package://rover_description/meshes/part_1.stl"/>
      </geometry>
      <material name="part_1_3_material">
        <color rgba="0.4 0.4 0.4 1"/>
      </material>
    </visual>
    <collision>
      <origin xyz="0 -0 -0" rpy="-3.14159 -0 -0"/>
      <geometry>
        <mesh filename="package://rover_description/meshes/part_1.stl"/>
      </geometry>
    </collision>
  </link>
  <!-- Joint from chassis to part_1_3 -->
  <joint name="FR_drive" type="revolute">
    <origin xyz="-0.494729 -0.0157296 -0.100958" rpy="1.5708 3.05199e-07 -3.9209e-08"/>
    <parent link="chassis"/>
    <child link="part_1_3"/>
    <axis xyz="0 0 1"/>
    <limit effort="10" velocity="10" lower="-3.141592653589793" upper="3.141592653589793"/>
  </joint>
  <!-- Link part_1_4 -->
  <link name="part_1_4">
    <inertial>
      <origin xyz="-0 0 -0.0475496" rpy="0 0 0"/>
      <mass value="5.36566"/>
      <inertia ixx="0.0699654" ixy="0" ixz="-0" iyy="0.0699654" iyz="-0" izz="0.12389"/>
    </inertial>
    <!-- Part part_1_4 -->
    <visual>
      <origin xyz="0 0 0" rpy="-3.14159 0 -0"/>
      <geometry>
        <mesh filename="package://rover_description/meshes/part_1.stl"/>
      </geometry>
      <material name="part_1_4_material">
        <color rgba="0.4 0.4 0.4 1"/>
      </material>
    </visual>
    <collision>
      <origin xyz="0 0 0" rpy="-3.14159 0 -0"/>
      <geometry>
        <mesh filename="package://rover_description/meshes/part_1.stl"/>
      </geometry>
    </collision>
  </link>
  <!-- Joint from chassis to part_1_4 -->
  <joint name="BR_drive" type="revolute">
    <origin xyz="-0.0375289 -0.0157296 -0.100958" rpy="1.5708 3.05199e-07 -3.9209e-08"/>
    <parent link="chassis"/>
    <child link="part_1_4"/>
    <axis xyz="0 0 1"/>
    <limit effort="10" velocity="10" lower="-3.141592653589793" upper="3.141592653589793"/>
  </joint>
  <!-- Link lidar -->
  <link name="lidar">
    <inertial>
      <origin xyz="0 -0 -0.0381" rpy="0 0 0"/>
      <mass value="1.2066"/>
      <inertia ixx="0.00180016" ixy="0" ixz="0" iyy="0.00180016" iyz="-0" izz="0.00243265"/>
    </inertial>
    <!-- Part lidar -->
    <visual>
      <origin xyz="0 0 -0" rpy="-3.14159 0 0"/>
      <geometry>
        <mesh filename="package://rover_description/meshes/lidar.stl"/>
      </geometry>
      <material name="lidar_material">
        <color rgba="0.372549 0.654902 0.239216 1"/>
      </material>
    </visual>
    <collision>
      <origin xyz="0 0 -0" rpy="-3.14159 0 0"/>
      <geometry>
        <mesh filename="package://rover_description/meshes/lidar.stl"/>
      </geometry>
    </collision>
  </link>
  <!-- Joint from chassis to lidar -->
  <joint name="chassis_lidar" type="fixed">
    <origin xyz="-0.494729 -0.20623 0.0514421" rpy="3.14159 3.05199e-07 -3.9209e-08"/>
    <parent link="chassis"/>
    <child link="lidar"/>
    <axis xyz="0 0 1"/>
    <limit effort="10" velocity="10"/>
  </joint>
  <!-- Link l0 -->
  <link name="l0">
    <inertial>
      <origin xyz="-0 -0.00273443 -0.0971396" rpy="0 0 0"/>
      <mass value="2.39104"/>
      <inertia ixx="0.00990806" ixy="0" ixz="-0" iyy="0.00914638" iyz="-0.000361301" izz="0.00427665"/>
    </inertial>
    <!-- Part l0 -->
    <visual>
      <origin xyz="-0 0 0.1016" rpy="3.14159 0 -0"/>
      <geometry>
        <mesh filename="package://rover_description/meshes/l0.stl"/>
      </geometry>
      <material name="l0_material">
        <color rgba="0.8 0.776471 0.713725 1"/>
      </material>
    </visual>
    <collision>
      <origin xyz="-0 0 0.1016" rpy="3.14159 0 -0"/>
      <geometry>
        <mesh filename="package://rover_description/meshes/l0.stl"/>
      </geometry>
    </collision>
  </link>
  <!-- Link l1 -->
  <link name="l1">
    <inertial>
      <origin xyz="0.0913043 0 -0.0508" rpy="0 0 0"/>
      <mass value="2.50551"/>
      <inertia ixx="0.00334246" ixy="0" ixz="-0" iyy="0.0150034" iyz="0" izz="0.0145766"/>
    </inertial>
    <!-- Part l1 -->
    <visual>
      <origin xyz="-0 0.254 -0.1524" rpy="1.5708 -0 -0"/>
      <geometry>
        <mesh filename="package://rover_description/meshes/l1.stl"/>
      </geometry>
      <material name="l1_material">
        <color rgba="0.8 0.776471 0.713725 1"/>
      </material>
    </visual>
    <collision>
      <origin xyz="-0 0.254 -0.1524" rpy="1.5708 -0 -0"/>
      <geometry>
        <mesh filename="package://rover_description/meshes/l1.stl"/>
      </geometry>
    </collision>
  </link>
  <!-- Link l2 -->
  <link name="l2">
    <inertial>
      <origin xyz="-0.003331 2.5e-11 -0.0963825" rpy="0 0 0"/>
      <mass value="1.96282"/>
      <inertia ixx="0.00691356" ixy="2e-12" ixz="-0.00036625" iyy="0.00799142" iyz="1e-12" izz="0.0033451"/>
    </inertial>
    <!-- Part l2 -->
    <visual>
      <origin xyz="-0.1016 0.254 0.2032" rpy="1.5708 1.5708 0"/>
      <geometry>
        <mesh filename="package://rover_description/meshes/l2.stl"/>
      </geometry>
      <material name="l2_material">
        <color rgba="0.8 0.776471 0.713725 1"/>
      </material>
    </visual>
    <collision>
      <origin xyz="-0.1016 0.254 0.2032" rpy="1.5708 1.5708 0"/>
      <geometry>
        <mesh filename="package://rover_description/meshes/l2.stl"/>
      </geometry>
    </collision>
  </link>
  <!-- Link l3 -->
  <link name="l3">
    <inertial>
      <origin xyz="0.0659696 -0 -0.0508" rpy="0 0 0"/>
      <mass value="1.96713"/>
      <inertia ixx="0.00259743" ixy="-0" ixz="-0" iyy="0.00827847" iyz="0" izz="0.00794865"/>
    </inertial>
    <!-- Part l3 -->
    <visual>
      <origin xyz="-0.3556 0.254 -0.0508" rpy="1.5708 0 -0"/>
      <geometry>
        <mesh filename="package://rover_description/meshes/l3.stl"/>
      </geometry>
      <material name="l3_material">
        <color rgba="0.8 0.776471 0.713725 1"/>
      </material>
    </visual>
    <collision>
      <origin xyz="-0.3556 0.254 -0.0508" rpy="1.5708 0 -0"/>
      <geometry>
        <mesh filename="package://rover_description/meshes/l3.stl"/>
      </geometry>
    </collision>
  </link>
  <!-- Link part_6 -->
  <link name="part_6">
    <inertial>
      <origin xyz="0.00259042 5.9e-11 -0.124353" rpy="0 0 0"/>
      <mass value="2.52457"/>
      <inertia ixx="0.0138994" ixy="3e-12" ixz="0.000515573" iyy="0.0151421" iyz="6e-12" izz="0.00425848"/>
    </inertial>
    <!-- Part part_6 -->
    <visual>
      <origin xyz="0 0.254 0.508" rpy="1.5708 1.5708 0"/>
      <geometry>
        <mesh filename="package://rover_description/meshes/part_6.stl"/>
      </geometry>
      <material name="part_6_material">
        <color rgba="0.8 0.776471 0.713725 1"/>
      </material>
    </visual>
    <collision>
      <origin xyz="0 0.254 0.508" rpy="1.5708 1.5708 0"/>
      <geometry>
        <mesh filename="package://rover_description/meshes/part_6.stl"/>
      </geometry>
    </collision>
  </link>
  <!-- Link part_7 -->
  <link name="part_7">
    <inertial>
      <origin xyz="0.0460155 0 -0.0508" rpy="0 0 0"/>
      <mass value="1.58137"/>
      <inertia ixx="0.00210371" ixy="0" ixz="-0" iyy="0.00446692" iyz="-0" izz="0.00419773"/>
    </inertial>
    <!-- Part part_7 -->
    <visual>
      <origin xyz="-0.7112 -0.254 0.0508" rpy="-1.5708 0 0"/>
      <geometry>
        <mesh filename="package://rover_description/meshes/part_7.stl"/>
      </geometry>
      <material name="part_7_material">
        <color rgba="0.8 0.776471 0.713725 1"/>
      </material>
    </visual>
    <collision>
      <origin xyz="-0.7112 -0.254 0.0508" rpy="-1.5708 0 0"/>
      <geometry>
        <mesh filename="package://rover_description/meshes/part_7.stl"/>
      </geometry>
    </collision>
  </link>
  <!-- Link part_8 -->
  <link name="part_8">
    <inertial>
      <origin xyz="3.1441e-08 -1.4282e-08 -0.0487831" rpy="0 0 0"/>
      <mass value="0.211137"/>
      <inertia ixx="0.000191412" ixy="-9.9e-11" ixz="3.34e-10" iyy="0.000205123" iyz="-3.5e-10" izz="5.92586e-05"/>
    </inertial>
    <!-- Part part_8 -->
    <visual>
      <origin xyz="-0.1016 0.254 0.8382" rpy="1.5708 1.5708 0"/>
      <geometry>
        <mesh filename="package://rover_description/meshes/part_8.stl"/>
      </geometry>
      <material name="part_8_material">
        <color rgba="0.498039 0.498039 0.498039 1"/>
      </material>
    </visual>
    <collision>
      <origin xyz="-0.1016 0.254 0.8382" rpy="1.5708 1.5708 0"/>
      <geometry>
        <mesh filename="package://rover_description/meshes/part_8.stl"/>
      </geometry>
    </collision>
  </link>
  <!-- Joint from part_7 to part_8 -->
  <joint name="l5_ee" type="revolute">
    <origin xyz="0.127 0 -0.0508" rpy="3.14159 1.5708 0"/>
    <parent link="part_7"/>
    <child link="part_8"/>
    <axis xyz="0 0 1"/>
    <limit effort="10" velocity="10" lower="-3.141592653589793" upper="3.141592653589793"/>
  </joint>
  <!-- Link camera -->
  <link name="camera">
    <inertial>
      <origin xyz="0 0 -0.0125" rpy="0 0 0"/>
      <mass value="0.264766"/>
      <inertia ixx="6.8741e-05" ixy="0" ixz="0" iyy="0.000647719" iyz="0" izz="0.000689297"/>
    </inertial>
    <!-- Part camera -->
    <visual>
      <origin xyz="-0.085725 -0.025 -0.025" rpy="-0 0 -0"/>
      <geometry>
        <mesh filename="package://rover_description/meshes/camera.stl"/>
      </geometry>
      <material name="camera_material">
        <color rgba="1 0 0 1"/>
      </material>
    </visual>
    <collision>
      <origin xyz="-0.085725 -0.025 -0.025" rpy="-0 0 -0"/>
      <geometry>
        <mesh filename="package://rover_description/meshes/camera.stl"/>
      </geometry>
    </collision>
  </link>
  <!-- Joint from part_7 to camera -->
  <joint name="EE_camera" type="fixed">
    <origin xyz="0.0508 0.04445 -0.0508" rpy="1.5708 1.5708 0"/>
    <parent link="part_7"/>
    <child link="camera"/>
    <axis xyz="0 0 1"/>
    <limit effort="10" velocity="10"/>
  </joint>
  <!-- Joint from part_6 to part_7 -->
  <joint name="l4_l5" type="revolute">
    <origin xyz="0.0508 -0 -0.2032" rpy="-3.14159 1.5708 0"/>
    <parent link="part_6"/>
    <child link="part_7"/>
    <axis xyz="0 0 1"/>
    <limit effort="10" velocity="10" lower="-3.141592653589793" upper="3.141592653589793"/>
  </joint>
  <!-- Joint from l3 to part_6 -->
  <joint name="l3_l4" type="fixed">
    <origin xyz="0.1524 -0 -0.0508" rpy="-0 -1.5708 0"/>
    <parent link="l3"/>
    <child link="part_6"/>
    <axis xyz="0 0 1"/>
    <limit effort="10" velocity="10"/>
  </joint>
  <!-- Joint from l2 to l3 -->
  <joint name="l2_l3" type="revolute">
    <origin xyz="-0.0508 0 -0.1524" rpy="-0 1.5708 0"/>
    <parent link="l2"/>
    <child link="l3"/>
    <axis xyz="0 0 1"/>
    <limit effort="10" velocity="10" lower="-3.141592653589793" upper="3.141592653589793"/>
  </joint>
  <!-- Joint from l1 to l2 -->
  <joint name="l1_l2" type="fixed">
    <origin xyz="0.2032 0 -0.0508" rpy="-0 -1.5708 0"/>
    <parent link="l1"/>
    <child link="l2"/>
    <axis xyz="0 0 1"/>
    <limit effort="10" velocity="10"/>
  </joint>
  <!-- Joint from l0 to l1 -->
  <joint name="l0_l1" type="revolute">
    <origin xyz="-0 -0.1524 -0.1524" rpy="1.5708 0 0"/>
    <parent link="l0"/>
    <child link="l1"/>
    <axis xyz="0 0 1"/>
    <limit effort="10" velocity="10" lower="-3.141592653589793" upper="3.141592653589793"/>
  </joint>
  <!-- Joint from chassis to l0 -->
  <joint name="base_l0" type="revolute">
    <origin xyz="-0.113729 -0.20623 0.153042" rpy="3.14159 3.05199e-07 -3.9209e-08"/>
    <parent link="chassis"/>
    <child link="l0"/>
    <axis xyz="0 0 1"/>
    <limit effort="10" velocity="10" lower="-3.141592653589793" upper="3.141592653589793"/>
  </joint>
</robot>
